Workbook

Sheet 調査票
B1: e-mail：kaitoku@jsps.go.jp | AC1: 令和 7年 12月 12日 | AO1: 現在
B2: 日本学術振興会 海外特別研究員担当 宛
G4: 海外特別研究員の就職状況等について（調査票） | AD4: ① | AF4: ＜様式3-3＞
B6: 氏 名 | X6: 受 付 番 号
B7: 萩原 佑紀 | AA7: （採用年度） | AJ7: （受付番号）
Y8: 令和 | AA8: 6 | AF8: 年度 | AJ8: 202406317
B10: ﾌ ﾘ ｶﾞ ﾅ | X10: 生 年 月 日
B11: =ASC(PHONETIC(B7)) -> ﾊｷﾞﾜﾗ ﾕｳｷ | X11: 35199
B13: 連 絡 先
B14: 〒 | E14: ： | F14: 5620031
B15: 住所 | E15: ： | F15: 大阪府箕面市小野原東2-10-16 石塚ハイム406
B18: 電話 | E18: ： | F18: 08058620514 | S18: メールアドレス | X18: ： | Y18: yhagiwara@biken.osaka-u.ac.jp
B19: 海外特別研究員申請時から現在までの職歴（略歴）を、以下にご記入願います。
B20: 職歴・略歴等 | T20: (資格Ⅰ・Ⅱ) | AO20: (常勤・非常勤等の別)
E21: ・ | F21: 海外特別研究員申請時 | T21: Ⅱ
E23: ・ | F23: 申請から派遣期間終了までの職歴
F24: ※ | G24: 職歴に変更があった場合のみ記入願います。資格（Ⅱ）で申請した有職者で、派遣開始前に職を辞した場合は、上段に辞職日を記入し、職名の後に「～（派遣開始前に辞職）」と付記願います。
F25: 令和 | I25: 年 | K25: 月 | L25: ～ | M25: 令和 | P25: 年 | R25: 月
F26: 令和 | I26: 年 | K26: 月 | L26: ～ | M26: 令和 | P26: 年 | R26: 月
E28: ・ | F28: 派遣期間終了 | M28: 令和 | O28: 7 | P28: 年 | Q28: 9 | R28: 月
E30: ・ | F30: 派遣期間終了後の職歴 | AO30: (常勤・非常勤等の別)
E31: 1. | F31: 令和 | H31: 7 | I31: 年 | J31: 10 | K31: 月 | L31: ～ | M31: 令和 | P31: 年 | R31: 月 | T31: 日本・大阪大学 微生物病研究所 特任助教 | AM31: 任期付
E32: 2. | F32: 令和 | I32: 年 | K32: 月 | L32: ～ | M32: 令和 | P32: 年 | R32: 月
E33: 3. | F33: 令和 | I33: 年 | K33: 月 | L33: ～ | M33: 令和 | P33: 年 | R33: 月
E34: =IF(H34=0,"","4.") | F34: =IF(H34=0,"","平成") | I34: =IF(H34=0,"","年") | K34: =IF(J34=0,"","月") | L34: =IF(J34=0,"","～") | M34: =IF(O34=0,"","平成") | P34: =IF(O34=0,"","年") | R34: =IF(Q34=0,"","月")
E35: =IF(H35=0,"","5.") | F35: =IF(H35=0,"","平成") | I35: =IF(H35=0,"","年") | K35: =IF(J35=0,"","月") | L35: =IF(J35=0,"","～") | M35: =IF(O35=0,"","平成") | P35: =IF(O35=0,"","年") | R35: =IF(Q35=0,"","月")
E36: =IF(H36=0,"","6.") | F36: =IF(H36=0,"","平成") | I36: =IF(H36=0,"","年") | K36: =IF(J36=0,"","月") | L36: =IF(J36=0,"","～") | M36: =IF(O36=0,"","平成") | P36: =IF(O36=0,"","年") | R36: =IF(Q36=0,"","月")
E37: =IF(H37=0,"","7.") | F37: =IF(H37=0,"","平成") | I37: =IF(H37=0,"","年") | K37: =IF(J37=0,"","月") | L37: =IF(J37=0,"","～") | M37: =IF(O37=0,"","平成") | P37: =IF(O37=0,"","年") | R37: =IF(Q37=0,"","月")
E38: =IF(H38=0,"","8.") | F38: =IF(H38=0,"","平成") | I38: =IF(H38=0,"","年") | K38: =IF(J38=0,"","月") | L38: =IF(J38=0,"","～") | M38: =IF(O38=0,"","平成") | P38: =IF(O38=0,"","年") | R38: =IF(Q38=0,"","月")
E39: =IF(H39=0,"","9.") | F39: =IF(H39=0,"","平成") | I39: =IF(H39=0,"","年") | K39: =IF(J39=0,"","月") | L39: =IF(J39=0,"","～") | M39: =IF(O39=0,"","平成") | P39: =IF(O39=0,"","年") | R39: =IF(Q39=0,"","月")
E42: 《入力・記入上の注意》
E43: ※ | F43: 本務職のみを記入してください（兼務職の記入は不要です。）。
E44: ※ | F44: 同時期に非常勤職等複数の職に就いている場合には、主たる勤務先一箇所の職務を記入してください。
E45: ※ | F45: 申請時及び申請から派遣期間終了までの職歴については、資格欄についてもご回答ください。
E46: ※ | F46: 「常勤・非常勤等の別」の欄には、「任期無、任期付、非常勤」の中から該当するものをご回答ください。
E47: ※ | F47: 所属機関名の前に国名を記入してください。
E49: ・記載例は下記のとおりです。
E50: 1. | F50: 令和 | H50: 4 | I50: 年 | J50: 4 | K50: 月 | L50: ～ | M50: 令和 | O50: 6 | P50: 年 | Q50: 3 | R50: 月 | T50: 米国・Guest Researcher, XXX Research Institute | AJ50: （非常勤）
E51: 2. | F51: 令和 | H51: 6 | I51: 年 | J51: 4 | K51: 月 | L51: ～ | M51: 令和 | O51: 9 | P51: 年 | Q51: 3 | R51: 月 | T51: 日本・○○大学工学部 助教 | AJ51: （任期付）
E52: 3. | F52: 令和 | H52: 9 | I52: 年 | J52: 4 | K52: 月 | L52: ～ | T52: 日本・○○大学大学院工学研究科 准教授（至現在） | AJ52: （任期無）
...

Sheet 集計票
B1: 0 | C1: 1 | D1: =C1+1 -> 2 | E1: =D1+1 -> 3 | F1: =E1+1 -> 4 | G1: =F1+1 -> 5 | H1: =G1+1 -> 6 | I1: =H1+1 -> 7 | J1: =I1+1 -> 8 | K1: =J1+1 -> 9 | ... FY1: =FX1+1 -> 179 | GA1: =FY1+1 -> 180 | GB1: =GA1+1 -> 181 | GC1: =GB1+1 -> 182 | GD1: =GC1+1 -> 183 | GE1: =GD1+1 -> 184 | GF1: =GE1+1 -> 185 | GG1: =GF1+1 -> 186 | GH1: =GG1+1 -> 187 | GI1: =GH1+1 -> 188 | ... HY1: =HX1+1 -> 230
A2: 設問 | C2: 基本情報 | H2: 連絡先 | L2: 海特申請時 | O2: 海特採用中職歴① | V2: 海特採用中職歴② | AC2: 海特終了 | AE2: 海特終了後職歴① | AK2: 海特終了後職歴② | AQ2: 海特終了後職歴③ | AW2: 海特終了後職歴④ | BC2: 海特終了後職歴⑤ | BI2: 海特終了後職歴⑥ | BO2: 海特終了後職歴⑦ | BU2: 海特終了後職歴⑧ | CA2: 海特終了後職歴⑨ | CG2: Ａ：採用開始時の身分・職との関係 | CM2: Ｂ－１：派遣中の扱い | CT2: Ｂ－２：申請時職と終了後職 | CX2: Ｃ－１：辞職の時期 | DC2: Ｃ－２：派遣中の扱い | DJ2: Ｃ－３：辞職と終了後職 | DO2: 問１ | DQ2: 問２－１ 勤務先 | DR2: 問２－１ 勤務先分類 | EB2: 問２－２ 雇用形態 | EH2: 任期付常勤の任期 | EO2: 問２－２ 職名①②③ <大学> | EW2: 問２－２ 職名①②③ <研究機関・民間企業> | EY2: 問２－２ 職名④⑤ | FE2: 問２－２ 職名⑥ | FI2: 問２－３ | FO2: 問２－４ ①②③ | FY2: 問２－５ | FZ2: 問２－６ | GA2: 問３－１ | GB2: 問３－２ ①専門職 | GK2: 問３－２ ②教育職 | GP2: 問３－２ ③技術職 | GT2: 問３－２ ④研究支援職 | GZ2: 問３－２ ⑤経営者・役員等 | HD2: 問３－２ ⑥事務職・営業職・その他 | HJ2: 問３－２ ⑦学生 | HO2: 問３－２ ⑧バイト等 | HP2: 問３－２ ⑨無職 | HQ2: 問３－２ ⑩その他 | HS2: 問３－３ | HX2: 問３－４ | HY2: 問３－５
A3: 項目 | B3: 回答日 | C3: 氏名 | D3: ﾌﾘｶﾞﾅ | E3: 生年月日 | F3: 採用年度 | G3: 受付番号 | H3: 〒 | I3: 住所 | J3: 電話 | K3: メールアドレス | L3: 資格 | M3: 職詳細 | N3: 任期・非常勤 | O3: 開始年 | P3: 開始月 | Q3: 終了年 | R3: 終了月 | S3: 資格 | T3: 職詳細 | U3: 任期・非常勤 | V3: 開始年 | W3: 開始月 | X3: 終了年 | Y3: 終了月 | Z3: 資格 | AA3: 職詳細 | AB3: 任期・非常勤 | AC3: 海特 終了年 | AD3: 海特 終了月 | AE3: 開始年 | AF3: 開始月 | AG3: 終了年 | AH3: 終了月 | AI3: 職詳細 | AJ3: 任期・非常勤 | AK3: 開始年 | AL3: 開始月 | AM3: 終了年 | AN3: 終了月 | AO3: 職詳細 | AP3: 任期・非常勤 | AQ3: 開始年 | AR3: 開始月 | AS3: 終了年 | AT3: 終了月 | AU3: 職詳細 | AV3: 任期・非常勤 | AW3: 開始年 | AX3: 開始月 | AY3: 終了年 | AZ3: 終了月 | BA3: 職詳細 | BB3: 任期・非常勤 | BC3: 開始年 | BD3: 開始月 | BE3: 終了年 | BF3: 終了月 | BG3: 職詳細 | BH3: 任期・非常勤 | BI3: 開始年 | BJ3: 開始月 | BK3: 終了年 | BL3: 終了月 | BM3: 職詳細 | BN3: 任期・非常勤 | BO3: 開始年 | BP3: 開始月 | BQ3: 終了年 | BR3: 終了月 | BS3: 職詳細 | BT3: 任期・非常勤 | BU3: 開始年 | BV3: 開始月 | BW3: 終了年 | BX3: 終了月 | BY3: 職詳細 | BZ3: 任期・非常勤 | CA3: 開始年 | CB3: 開始月 | CC3: 終了年 | CD3: 終了月 | CE3: 職詳細 | CF3: 任期・非常勤 | CG3: 1：常勤・留任 | CH3: 2：常勤（任期付）・留任 | CI3: 3：常勤・辞職 | CJ3: 4：常勤（任期付）・辞職 | CK3: 5：常勤（任期付）・任期満了 | CL3: 6：資格Ⅱ | CM3: 1：休職 | CN3: 2：出張 | CO3: 3：留学・研修 | CP3: 4：その他 | CQ3: その他詳細 | CR3: 1：有給 | CS3: 1：サバティカル利用あり | CT3: 1：申請時の職を継続 | CU3: 2：辞職し別職 | CV3: 3：その他 | CW3: その他詳細 | CX3: 1：申請から採用前 | CY3: 2：採用に伴い | CZ3: 3：採用中 | DA3: 4：その他 | DB3: その他詳細 | DC3: 1：休職 | DD3: 2：出張 | DE3: 3：留学・研修 | DF3: 4：その他 | DG3: その他詳細 | DH3: 1：有給 | DI3: 1：サバティカル利用あり | DJ3: 1：前職に復帰 | DK3: 2：前職とは別職 | DL3: 3：終了後未就職 | DM3: 4：その他 | DN3: その他詳細 | DO3: 1：研究職 | DP3: 2：非研究職等 | DQ3: 機関名および部局名・部署名 | DR3: 1：国立大学法人 | DS3: 2：公立大学 | DT3: 3：私立大学 | DU3: 4：高等専門学校 | DV3: 5：海外の大学 | DW3: 6：国公立（独法含む）の研究機関等 | DX3: 7：海外の研究機関等 | DY3: 8：財団等研究法人 | DZ3: 9：民間企業 | EA3: 10：海外の民間企業 | EB3: 1：常勤（任期なし） | EC3: 2：常勤（ﾃﾆｭｱﾄﾗｯｸ） | ED3: 3：常勤（任期付） | EE3: 4：ﾌｪﾛｰｼｯﾌﾟ | EF3: 5：ﾎﾟｽﾄﾞｸ | EG3: 6：週30時間未満 | EH3: 開始年 | EI3: 開始月 | EJ3: 終了年 | EK3: 終了月 | EL3: 更新有り | EM3: 最長更新年数 | EN3: 更新無し | EO3: 1：教授 | EP3: 2：准教授 | EQ3: 3：講師 | ER3: 4：助教 | ES3: 5：助手 | ET3: 6：研究員 | EU3: 7：その他 | EV3: その他詳細 | EW3: 8：ＰＩ | EX3: 9：その他の研究員等 | EY3: 10：ﾌｪﾛｰｼｯﾌﾟ | EZ3: 事業・制度名 | FA3: 11：ﾎﾟｽﾄﾞｸ | FB3: 雇用財源名 | FC3: 12：その他 | FD3: その他詳細 | FE3: 13：非常勤講師 | FF3: 14：非常勤研究員 | FG3: 15：その他 | FH3: その他詳細 | FI3: 1：非常に役に立った | FJ3: 2：役立った | FK3: 3：どちらかと言えば役だった | FL3: 4：どちらとも言えない | FM3: 5：役立たなかった | FN3: ④⑤の理由 | FO3: 1：研究能力身についた | FP3: 2：現在につながる | FQ3: 3：自分のテーマ | FR3: 4：経済的不安 | FS3: 5：海外経験 | FT3: 6：業績増えた | FU3: 7：人脈・交流 | FV3: 8：就職に役立った | FW3: 9：その他 | FX3: その他詳細 | FY3: 受賞歴 | FZ3: その他意見 | GA3: 勤務先 | GB3: 1-1：医師 | GC3: 1-2：弁護士 | GD3: 1-3：弁理士 | GE3: 1-4：サイエンスライター | GF3: 1-5：学芸員 | GG3: 1-6：特許審査官 | GH3: 1-7：コンサルタント | GI3: 1-8：その他 | GJ3: その他詳細 | GK3: 2-1：大学等高等教育機関 | GL3: 2-2：高等専門学校 | GM3: 2-3：高校 | GN3: 2-4：その他 | GO3: その他詳細 | GP3: 3-1：民間企業の製品開発部門、工場部門等 | GQ3: 3-2：大学・研究機関のテクニシャン、研究補助職 | GR3: 3-3：その他 | GS3: その他詳細 | GT3: 4-1：大学事務職員 | GU3: 4-2：研究機関事務職員 | GV3: 4-3：ＴＬＯ | GW3: 4-4：ファンディングエージェンシー | GX3: 4-5：その他 | GY3: その他詳細 | GZ3: 5-1：民間企業（*ベンチャー創業を除く） | HA3: 5-2：ベンチャー創業 | HB3: 5-3：その他 | HC3: その他詳細 | HD3: 6-：公的機関 | HE3: 6-2：民間企業 | HF3: 6-3：財団 | HG3: 6-4：ＮＰＯ | HH3: 6-5：その他 | HI3: その他詳細 | HJ3: 7-1：研究生、研修生 | HK3: 7-2：大学院生 | HL3: 7-3：国外留学 | HM3: 7-4：その他 | HN3: その他詳細 | HO3: 8：パートアルバイト | HP3: 9：無職 | HQ3: 10：その他 | HR3: その他詳細 | HS3: 1：非常に役に立った | HT3: 2：役立った | HU3: 3：どちらかと言えば役だった | HV3: 4：どちらとも言えない | HW3: 5：役立たなかった | HX3: 理由 | HY3: 意見・要望
A4: チェック情報(TRUE or FALSE) | CG4: FALSE | CH4: FALSE | CI4: FALSE | CJ4: FALSE | CK4: FALSE | CL4: TRUE | CM4: FALSE | CN4: FALSE | CO4: FALSE | CP4: FALSE | CR4: FALSE | CS4: FALSE | CT4: FALSE | CU4: FALSE | CV4: FALSE | CX4: FALSE | CY4: FALSE | CZ4: FALSE | DA4: FALSE | DC4: FALSE | DD4: FALSE | DE4: FALSE | DF4: FALSE | DH4: FALSE | DI4: FALSE | DJ4: FALSE | DK4: FALSE | DL4: FALSE | DM4: FALSE | DO4: TRUE | DP4: FALSE | DR4: TRUE | DS4: FALSE | DT4: FALSE | DU4: FALSE | DV4: FALSE | DW4: FALSE | DX4: FALSE | DY4: FALSE | DZ4: FALSE | EA4: FALSE | EB4: FALSE | EC4: FALSE | ED4: TRUE | EE4: FALSE | EF4: FALSE | EG4: FALSE | EL4: TRUE | EN4: FALSE | EO4: FALSE | EP4: FALSE | EQ4: FALSE | ER4: TRUE | ES4: FALSE | ET4: FALSE | EU4: FALSE | EW4: FALSE | EX4: FALSE | EY4: FALSE | FA4: FALSE | FC4: FALSE | FE4: FALSE | FF4: FALSE | FG4: FALSE | FI4: FALSE | FJ4: TRUE | FK4: FALSE | FL4: FALSE | FM4: FALSE | FO4: TRUE | FP4: FALSE | FQ4: FALSE | FR4: TRUE | FS4: TRUE | FT4: FALSE | FU4: TRUE | FV4: FALSE | FW4: FALSE | GB4: FALSE | GC4: FALSE | GD4: FALSE | GE4: FALSE | GF4: FALSE | GG4: FALSE | GH4: FALSE | GI4: FALSE | GK4: FALSE | GL4: FALSE | GM4: FALSE | GN4: FALSE | GP4: FALSE | GQ4: FALSE | GR4: FALSE | GT4: FALSE | GU4: FALSE | GV4: FALSE | GW4: FALSE | GX4: FALSE | GZ4: FALSE | HA4: FALSE | HB4: FALSE | HD4: FALSE | HE4: FALSE | HF4: FALSE | HG4: FALSE | HH4: FALSE | HJ4: FALSE | HK4: FALSE | HL4: FALSE | HM4: FALSE | HO4: FALSE | HP4: FALSE | HQ4: FALSE | HS4: FALSE | HT4: FALSE | HU4: FALSE | HV4: FALSE | HW4: FALSE
A5: データ集計用フィールド | B5: =調査票!AC1 -> 令和 7年 12月 12日 | C5: =調査票!B7 -> 萩原 佑紀 | D5: =調査票!B11 -> ﾊｷﾞﾜﾗ ﾕｳｷ | E5: =調査票!X11 -> 35199 | F5: =調査票!AA8 -> 6 | G5: =調査票!AJ8 -> 202406317 | H5: =調査票!F14 -> 5620031 | I5: =調査票!F15 -> 大阪府箕面市小野原東2-10-16 石塚ハイム406 | J5: =調査票!F18 -> 08058620514 | K5: =調査票!Y18 -> yhagiwara@biken.osaka-u.ac.jp | L5: =調査票!T21 -> Ⅱ | M5: =調査票!V21 -> 0 | N5: =調査票!AM21 -> 0 | O5: =調査票!H25 -> 0 | P5: =調査票!J25 -> 0 | Q5: =調査票!O25 -> 0 | R5: =調査票!Q25 -> 0 | S5: =調査票!T25 -> 0 | T5: =調査票!V25 -> 0 | U5: =調査票!AM25 -> 0 | V5: =調査票!H26 -> 0 | W5: =調査票!J26 -> 0 | X5: =調査票!O26 -> 0 | Y5: =調査票!Q26 -> 0 | Z5: =調査票!T26 -> 0 | AA5: =調査票!V26 -> 0 | AB5: =調査票!AM26 -> 0 | AC5: =調査票!O28 -> 7 | AD5: =調査票!Q28 -> 9 | AE5: =調査票!H31 -> 7 | AF5: =調査票!J31 -> 10 | AG5: =調査票!O31 -> 0 | AH5: =調査票!Q31 -> 0 | AI5: =調査票!T31 -> 日本・大阪大学 微生物病研究所 特任助教 | AK5: =調査票!H32 -> 0 | AL5: =調査票!J32 -> 0 | AM5: =調査票!O32 -> 0 | AN5: =調査票!Q32 -> 0 | AO5: =調査票!T32 -> 0 | AQ5: =調査票!H33 -> 0 | AR5: =調査票!J33 -> 0 | AS5: =調査票!O33 -> 0 | AT5: =調査票!Q33 -> 0 | AU5: =調査票!T33 -> 0 | AW5: =調査票!H34 -> 0 | AX5: =調査票!J34 -> 0 | AY5: =調査票!O34 -> 0 | AZ5: =調査票!Q34 -> 0 | BA5: =調査票!T34 -> 0 | BB5: =調査票!AM34 -> 0 | BC5: =調査票!H35 -> 0 | BD5: =調査票!J35 -> 0 | BE5: =調査票!O35 -> 0 | BF5: =調査票!Q35 -> 0 | BG5: =調査票!T35 -> 0 | BH5: =調査票!AM35 -> 0 | BI5: =調査票!H36 -> 0 | BJ5: =調査票!J36 -> 0 | BK5: =調査票!O36 -> 0 | BL5: =調査票!Q36 -> 0 | BM5: =調査票!T36 -> 0 | BN5: =調査票!AM36 -> 0 | BO5: =調査票!H37 -> 0 | BP5: =調査票!J37 -> 0 | BQ5: =調査票!O37 -> 0 | BR5: =調査票!Q37 -> 0 | BS5: =調査票!T37 -> 0 | BT5: =調査票!AM37 -> 0 | BU5: =調査票!H38 -> 0 | BV5: =調査票!J38 -> 0 | BW5: =調査票!O38 -> 0 | BX5: =調査票!Q38 -> 0 | BY5: =調査票!T38 -> 0 | BZ5: =調査票!AM38 -> 0 | CA5: =調査票!H39 -> 0 | CB5: =調査票!J39 -> 0 | CC5: =調査票!O39 -> 0 | CD5: =調査票!Q39 -> 0 | CE5: =調査票!T39 -> 0 | CF5: =調査票!AM39 -> 0 | CG5: =IF(CG4=TRUE,CG3,"") | CH5: =IF(CH4=TRUE,CH3,"") | CI5: =IF(CI4=TRUE,CI3,"") | CJ5: =IF(CJ4=TRUE,CJ3,"") | CK5: =IF(CK4=TRUE,CK3,"") | CL5: =IF(CL4=TRUE,CL3,"") -> 6：資格Ⅱ | CM5: =IF(CM4=TRUE,CM3,"") | CN5: =IF(CN4=TRUE,CN3,"") | ... CP5: =IF(CP4=TRUE,CP3,"") | CQ5: =調査票!L82 -> 0 | CR5: =IF(CR4=TRUE,CR3,"2：無給") -> 2：無給 | CS5: =IF(CS4=TRUE,CS3,"2：サバティカル利用なし") -> 2：サバティカル利用なし | CT5: =IF(CT4=TRUE,CT3,"") | CU5: =IF(CU4=TRUE,CU3,"") | CV5: =IF(CV4=TRUE,CV3,"") | CW5: =調査票!L91 -> 0 | CX5: =IF(CX4=TRUE,CX3,"") | CY5: =IF(CY4=TRUE,CY3,"") | CZ5: =IF(CZ4=TRUE,CZ3,"") | DA5: =IF(DA4=TRUE,DA3,"") | DB5: =調査票!L100 -> 0 | DC5: =IF(DC4=TRUE,DC3,"") | DD5: =IF(DD4=TRUE,DD3,"") | DE5: =IF(DE4=TRUE,DE3,"") | DF5: =IF(DF4=TRUE,DF3,"") | DG5: =調査票!L109 -> 0 | DH5: =IF(DH4=TRUE,DH3,"2：無給") -> 2：無給 | DI5: =IF(DI4=TRUE,DI3,"2：サバティカル利用なし") -> 2：サバティカル利用なし | DJ5: =IF(DJ4=TRUE,DJ3,"") | DK5: =IF(DK4=TRUE,DK3,"") | DL5: =IF(DL4=TRUE,DL3,"") | DM5: =IF(DM4=TRUE,DM3,"") | DN5: =調査票!L119 -> 0 | DO5: =IF(DO4=TRUE,DO3,"") -> 1：研究職 | DP5: =IF(DP4=TRUE,DP3,"") | DQ5: =調査票!G147 -> 大阪大学 微生物病研究所 | DR5: =IF(DR4=TRUE,DR3,"") -> 1：国立大学法人 | DS5: =IF(DS4=TRUE,DS3,"") | DT5: =IF(DT4=TRUE,DT3,"") | DU5: =IF(DU4=TRUE,DU3,"") | DV5: =IF(DV4=TRUE,DV3,"") | DW5: =IF(DW4=TRUE,DW3,"") | DX5: =IF(DX4=TRUE,DX3,"") | DY5: =IF(DY4=TRUE,DY3,"") | ... EG5: =IF(EG4=TRUE,EG3,"") | EH5: =調査票!J164 -> 7 | EI5: =調査票!L164 -> 10 | EJ5: =調査票!P164 -> 8 | EK5: =調査票!R164 -> 3 | EL5: =IF(EL4=TRUE,EL3,"") -> 更新有り | EM5: =調査票!AE164 -> 3 | EN5: =IF(EN4=TRUE,EN3,"") | EO5: =IF(EO4=TRUE,EO3,"") | EP5: =IF(EP4=TRUE,EP3,"") | EQ5: =IF(EQ4=TRUE,EQ3,"") | ER5: =IF(ER4=TRUE,ER3,"") -> 4：助教 | ES5: =IF(ES4=TRUE,ES3,"") | ET5: =IF(ET4=TRUE,ET3,"") | EU5: =IF(EU4=TRUE,EU3,"") | EV5: =調査票!M178 -> 0 | EW5: =IF(EW4=TRUE,EW3,"") | EX5: =IF(EX4=TRUE,EX3,"") | EY5: =IF(EY4=TRUE,EY3,"") | EZ5: =調査票!U185 -> 0 | FA5: =IF(FA4=TRUE,FA3,"") | FB5: =調査票!U187 -> 0 | FC5: =IF(FC4=TRUE,FC3,"") | FD5: =調査票!N189 -> 0 | FE5: =IF(FE4=TRUE,FE3,"") | FF5: =IF(FF4=TRUE,FF3,"") | FG5: =IF(FG4=TRUE,FG3,"") | FH5: =調査票!N195 -> 0 | FI5: =IF(FI4=TRUE,FI3,"") | FJ5: =IF(FJ4=TRUE,FJ3,"") -> 2：役立った | FK5: =IF(FK4=TRUE,FK3,"") | FL5: =IF(FL4=TRUE,FL3,"") | FM5: =IF(FM4=TRUE,FM3,"") | FN5: =調査票!G213 -> 0 | FO5: =IF(FO4=TRUE,FO3,"") -> 1：研究能力身についた | FP5: =IF(FP4=TRUE,FP3,"") | FQ5: =IF(FQ4=TRUE,FQ3,"") | FR5: =IF(FR4=TRUE,FR3,"") -> 4：経済的不安 | FS5: =IF(FS4=TRUE,FS3,"") -> 5：海外経験 | FT5: =IF(FT4=TRUE,FT3,"") | FU5: =IF(FU4=TRUE,FU3,"") -> 7：人脈・交流 | FV5: =IF(FV4=TRUE,FV3,"") | FW5: =IF(FW4=TRUE,FW3,"") | FX5: =調査票!G234 -> 0 | FY5: =調査票!G243 -> 第41回井上研究奨励賞、公益財団法人 井上科学振興財団、光熱効果による有機結晶の高速アクチュエーション、2025年2月5日 | FZ5: =調査票!G249 -> 特になし | GA5: =調査票!G268 -> 0 | GB5: =IF(GB4=TRUE,GB3,"") | GC5: =IF(GC4=TRUE,GC3,"") | GD5: =IF(GD4=TRUE,GD3,"") | GE5: =IF(GE4=TRUE,GE3,"") | GF5: =IF(GF4=TRUE,GF3,"") | GG5: =IF(GG4=TRUE,GG3,"") | GH5: =IF(GH4=TRUE,GH3,"") | GI5: =IF(GI4=TRUE,GI3,"") | GJ5: =調査票!L279 -> 0 | GK5: =IF(GK4=TRUE,GK3,"") | GL5: =IF(GL4=TRUE,GL3,"") | GM5: =IF(GM4=TRUE,GM3,"") | GN5: =IF(GN4=TRUE,GN3,"") | GO5: =調査票!L284 -> 0 | GP5: =IF(GP4=TRUE,GP3,"") | GQ5: =IF(GQ4=TRUE,GQ3,"") | GR5: =IF(GR4=TRUE,GR3,"") | GS5: =調査票!L289 -> 0 | GT5: =IF(GT4=TRUE,GT3,"") | GU5: =IF(GU4=TRUE,GU3,"") | GV5: =IF(GV4=TRUE,GV3,"") | GW5: =IF(GW4=TRUE,GW3,"") | GX5: =IF(GX4=TRUE,GX3,"") | GY5: =調査票!L294 -> 0 | GZ5: =IF(GZ4=TRUE,GZ3,"") | HA5: =IF(HA4=TRUE,HA3,"") | HB5: =IF(HB4=TRUE,HB3,"") | HC5: =調査票!L299 -> 0 | HD5: =IF(HD4=TRUE,HD3,"") | HE5: =IF(HE4=TRUE,HE3,"") | HF5: =IF(HF4=TRUE,HF3,"") | HG5: =IF(HG4=TRUE,HG3,"") | HH5: =IF(HH4=TRUE,HH3,"") | HI5: =調査票!L304 -> 0 | HJ5: =IF(HJ4=TRUE,HJ3,"") | HK5: =IF(HK4=TRUE,HK3,"") | HL5: =IF(HL4=TRUE,HL3,"") | HM5: =IF(HM4=TRUE,HM3,"") | HN5: =調査票!L309 -> 0 | HO5: =IF(HO4=TRUE,HO3,"") | HP5: =IF(HP4=TRUE,HP3,"") | HQ5: =IF(HQ4=TRUE,HQ3,"") | HR5: =調査票!G316 -> 0 | HS5: =IF(HS4=TRUE,HS3,"") | HT5: =IF(HT4=TRUE,HT3,"") | HU5: =IF(HU4=TRUE,HU3,"") | HV5: =IF(HV4=TRUE,HV3,"") | HW5: =IF(HW4=TRUE,HW3,"") | HX5: =調査票!G340 -> 0 | HY5: =調査票!G351 -> 0
A7: ※ データ提出時には、入力されたデータの集計に必要ですので、「集計票」も含めて本会に提出（メールにて送信）してください。
